# Exception
x = 0
try: 
    x == 2
except Exception as exception_name:
    print(exception_name)